---
title: 005 手写Promise
date: 2021-07-20
categories:
  - JavaScript
tags:
  - JS基础
sidebar: "auto"
---
## promise解决了什么问题：
1. 链式调用解决嵌套回调问题 
2. 同步并发问题

## promise的特点
1. promise是一个类
2. 当使用promise时，会传入一个执行器（executor），默认此执行器会默认执行
3. 当前executor给了函数可以描述当前promise的状态。promise中有三个状态：成功态、失败态、等待态，默认为等待态，
如果调用resolve会变为成功态，如果调用reject或者出现异常，会变为失败态
4. 每一个promise实例都有一个then方法
5. promise状态一旦发生变化就不能更改
6. promise的链式调用：当调用then方法后会返回一个新的promise（为什么返回新的，见第五点）
    - 情况1：then方法返回的是一个普通值，这个值会作为外层下一次then的成功结果
    - 情况2：then方法中执行出错，会走到外层下一次then的失败结果
无论上一次then走的是成功还是失败，只要返回的是普通值，都会执行下一次then的成功

总结：如果返回一个普通值（除了promise）就会传递给下一个then的成功，如果返回一个失败的promise或者抛出异常，会走下一个then的失败


```js
const PENDING = 'PENDING'
const FULFILLED = 'FULFILLED'
const REJECTED = 'REJECTED'

function resolvePromise(promise2, x, resolve, reject) {
    if (promise2 === x) {
        return reject(new TypeError('TypeError: Chaining cycle detected for promise #<Promise>'));
    }
    if (typeof x === 'function' || (typeof x === 'object' && x !== null)) {
        // called变量是为了兼容别的promise 状态一旦变化就不能再变更了
        let called = false
        try {
            const then = x.then
            if (typeof then === 'function') {
                then.call(x, y => {
                    if (called) return
                    called = true
                    resolvePromise(promise2, y, resolve, reject)
                }, r => {
                    if (called) return
                    called = true
                    reject(r)
                })
            } else {
                resolve(x)
            }
        } catch (error) {
            if (called) return
            called = true
            reject(error)
        }
    } else {
        resolve(x)
    }
}
class Promise {
    constructor(executor) {
        this.status = PENDING
        this.value = undefined
        this.reason = undefined
        this.onResolvedCallbacks = []
        this.onRejectedCallbacks = []
        const resolve = (value) => {
            if (this.status === PENDING) {
                this.status = FULFILLED
                this.value = value
                this.onResolvedCallbacks.forEach(fn => fn())
            }
        }
        const reject = (reason) => {
            if (this.status === PENDING) {
                this.status = REJECTED
                this.reason = reason
                this.onRejectedCallbacks.forEach(fn => fn())
            }
        }
        try {
            executor(resolve, reject)
        } catch (error) {
            reject(error)
        }
    }
    then(onFulfilled, onRejected) {
        // then方法的参数可选
        onFulfilled = typeof onFulfilled === 'function' ? onFulfilled : val => val
        onRejected = typeof onRejected === 'function' ? onRejected : (reason) => {
            throw reason
        }
        const promise2 = new Promise((resolve, reject) => {
            if (this.status === PENDING) {
                this.onResolvedCallbacks.push(() => {
                    setTimeout(() => {
                        try {
                            const x = onFulfilled(this.value)
                            resolvePromise(promise2, x, resolve, reject)
                        } catch (error) {
                            reject(error)
                        }
                    }, 0)


                })
                this.onRejectedCallbacks.push(() => {
                    setTimeout(() => {
                        try {
                            const x = onRejected(this.reason)
                            resolvePromise(promise2, x, resolve, reject)
                        } catch (error) {
                            reject(error)
                        }
                    }, 0)
                })
            }
            if (this.status === FULFILLED) {
                setTimeout(() => {
                    try {
                        const x = onFulfilled(this.value)
                        resolvePromise(promise2, x, resolve, reject)
                    } catch (error) {
                        reject(error)
                    }
                }, 0)

            }
            if (this.status === REJECTED) {
                setTimeout(() => {
                    try {
                        const x = onRejected(this.reason)
                        resolvePromise(promise2, x, resolve, reject)
                    } catch (error) {
                        reject(error)
                    }
                }, 0)
            }
        })
        return promise2
    }
    catch(err){
        return this.then(null,err)
    }
    static resolve(val){
        return new Promise((resolve,reject)=>{
            resolve(val);
        }) 
    }
    static reject(reason){
        return new Promise((resolve,reject)=>{
            reject(reason);
        })
    }
}

// 测试时会调用此方法
Promise.deferred = function () {
    const dfd = {}
    dfd.promise = new Promise((resolve, reject) => {
        dfd.resolve = resolve
        dfd.reject = reject
    })
    return dfd
}
// 测试包安装：npm install promises-aplus-tests -g 
// 测试命令：promises-aplus-tests 文件名
module.exports = Promise
```

## promise的局限性
1. 顺序错误处理
2. 单一值
3. 单决议
4. 惯性（从回调函数改造成promise）
5. 无法取消的promise
6. promise性能
